Workbook

Sheet pay data
A1: net pnl | B1: 880000 | C1: =B1*0.7 -> 616000 | G1: net liq | H1: 1843600
A2: salary | B2: 115000 | G2: energy | H2: -110860
A3: current bonus | B3: 34200 | G3: expense | H3: -171902
H4: =SUM(H1:H3) -> 1560838
A5: Distribution | B5: Total Pay | C5: Addt'l Pay | D5: % | G5: ytd | H5: 193200
A6: 250000 | B6: 115000 | C6: =B6-$B$2 -> 0 | D6: =B6/A6 -> 0.46 | E6: =A6*0.7 -> 175000 | F6: =B6/E6 -> 0.65714286 | G6: last yr adj | H6: -15295
A7: 500000 | B7: 135000 | C7: =B7-$B$2 -> 20000 | D7: =B7/A7 -> 0.27 | E7: =A7*0.7 -> 350000 | F7: =B7/E7 -> 0.38571429 | G7: fut pay | H7: 0
A8: 750000 | B8: 155000 | C8: =B8-$B$2 -> 40000 | D8: =B8/A8 -> 0.20666667 | E8: =A8*0.7 -> 525000 | F8: =B8/E8 -> 0.2952381 | H8: =SUM(H5:H7) -> 177905
A9: 1000000 | B9: 167000 | C9: =B9-$B$2 -> 52000 | D9: =B9/A9 -> 0.167 | E9: =A9*0.7 -> 700000 | F9: =B9/E9 -> 0.23857143
A10: 1250000 | B10: 187000 | C10: =B10-$B$2 -> 72000 | D10: =B10/A10 -> 0.1496 | E10: =A10*0.7 -> 875000 | F10: =B10/E10 -> 0.21371429 | H10: =H8+H4 -> 1738743
A11: 1500000 | B11: 208000 | C11: =B11-$B$2 -> 93000 | D11: =B11/A11 -> 0.13866667 | E11: =A11*0.7 -> 1050000 | F11: =B11/E11 -> 0.19809524 | H11: =H10/A13 -> 0.8693715
A12: 1750000 | B12: 228000 | C12: =B12-$B$2 -> 113000 | D12: =B12/A12 -> 0.13028571 | E12: =A12*0.7 -> 1225000 | F12: =B12/E12 -> 0.18612245 | H12: =H11*B13 -> 219081.62
A13: 2000000 | B13: 252000 | C13: =B13-$B$2 -> 137000 | D13: =B13/A13 -> 0.126 | E13: =A13*0.7 -> 1400000 | F13: =B13/E13 -> 0.18
A14: 2250000 | B14: 272000 | C14: =B14-$B$2 -> 157000 | D14: =B14/A14 -> 0.12088889 | E14: =A14*0.7 -> 1575000 | F14: =B14/E14 -> 0.17269841 | H14: =H12-H8 -> 41176.618
A15: 2500000 | B15: 292000 | C15: =B15-$B$2 -> 177000 | D15: =B15/A15 -> 0.1168 | E15: =A15*0.7 -> 1750000 | F15: =B15/E15 -> 0.16685714
A16: 2750000 | B16: 316000 | C16: =B16-$B$2 -> 201000 | D16: =B16/A16 -> 0.11490909 | E16: =A16*0.7 -> 1925000 | F16: =B16/E16 -> 0.16415584
A17: 3000000 | B17: 340000 | C17: =B17-$B$2 -> 225000 | D17: =B17/A17 -> 0.11333333 | E17: =A17*0.7 -> 2100000 | F17: =B17/E17 -> 0.16190476
A18: 3250000 | B18: 360000 | C18: =B18-$B$2 -> 245000 | D18: =B18/A18 -> 0.11076923 | E18: =A18*0.7 -> 2275000 | F18: =B18/E18 -> 0.15824176
A19: 3500000 | B19: 380000 | C19: =B19-$B$2 -> 265000 | D19: =B19/A19 -> 0.10857143 | E19: =A19*0.7 -> 2450000 | F19: =B19/E19 -> 0.15510204 | H19: =1522279+23000 -> 1545279
A20: 3750000 | B20: 400000 | C20: =B20-$B$2 -> 285000 | D20: =B20/A20 -> 0.10666667 | E20: =A20*0.7 -> 2625000 | F20: =B20/E20 -> 0.15238095
A21: 4000000 | B21: 420000 | C21: =B21-$B$2 -> 305000 | D21: =B21/A21 -> 0.105 | E21: =A21*0.7 -> 2800000 | F21: =B21/E21 -> 0.15 | H21: =H19+H5 -> 1738479
A22: 4250000 | B22: 440000 | C22: =B22-$B$2 -> 325000 | D22: =B22/A22 -> 0.10352941 | E22: =A22*0.7 -> 2975000 | F22: =B22/E22 -> 0.14789916
A23: 4500000 | B23: 460000 | C23: =B23-$B$2 -> 345000 | D23: =B23/A23 -> 0.10222222 | E23: =A23*0.7 -> 3150000 | F23: =B23/E23 -> 0.14603175
A24: 4750000 | B24: 480000 | C24: =B24-$B$2 -> 365000 | D24: =B24/A24 -> 0.10105263 | E24: =A24*0.7 -> 3325000 | F24: =B24/E24 -> 0.1443609
A25: 5000000 | B25: 500000 | C25: =B25-$B$2 -> 385000 | D25: =B25/A25 -> 0.1 | E25: =A25*0.7 -> 3500000 | F25: =B25/E25 -> 0.14285714
A26: 5250000 | B26: 520000 | C26: =B26-$B$2 -> 405000 | D26: =B26/A26 -> 0.099047619 | E26: =A26*0.7 -> 3675000 | F26: =B26/E26 -> 0.1414966
A27: 5500000 | B27: 540000 | C27: =B27-$B$2 -> 425000 | D27: =B27/A27 -> 0.098181818 | E27: =A27*0.7 -> 3850000 | F27: =B27/E27 -> 0.14025974
A28: 5750000 | B28: 560000 | C28: =B28-$B$2 -> 445000 | D28: =B28/A28 -> 0.097391304 | E28: =A28*0.7 -> 4025000 | F28: =B28/E28 -> 0.13913043
A29: 6000000 | B29: 580000 | C29: =B29-$B$2 -> 465000 | D29: =B29/A29 -> 0.096666667 | E29: =A29*0.7 -> 4200000 | F29: =B29/E29 -> 0.13809524
A30: 6250000 | B30: 600000 | C30: =B30-$B$2 -> 485000 | D30: =B30/A30 -> 0.096 | E30: =A30*0.7 -> 4375000 | F30: =B30/E30 -> 0.13714286
A31: 6500000 | B31: 620000 | C31: =B31-$B$2 -> 505000 | D31: =B31/A31 -> 0.095384615 | E31: =A31*0.7 -> 4550000 | F31: =B31/E31 -> 0.13626374
A32: 6750000 | B32: 640000 | C32: =B32-$B$2 -> 525000 | D32: =B32/A32 -> 0.094814815 | E32: =A32*0.7 -> 4725000 | F32: =B32/E32 -> 0.13544974
A33: 7000000 | B33: 660000 | C33: =B33-$B$2 -> 545000 | D33: =B33/A33 -> 0.094285714 | E33: =A33*0.7 -> 4900000 | F33: =B33/E33 -> 0.13469388
... A45: 10000000 | B45: 900000 | C45: =B45-$B$2 -> 785000 | D45: =B45/A45 -> 0.09 | E45: =A45*0.7 -> 7000000 | F45: =B45/E45 -> 0.12857143

Sheet PnL Data
A1: % days positive | B1: =COUNTIF('Daily PnL Log'!$J$3:$J$1972,">0")/COUNT('Daily PnL Log'!$J$3:$J$1972) -> 0.54732824
A2: % days negative | B2: =COUNTIF('Daily PnL Log'!$J$3:$J$1972,"<0")/COUNT('Daily PnL Log'!$J$3:$J$1972) -> 0.45267176
A4: avg up day | B4: =AVERAGEIF('Daily PnL Log'!$J$3:$J$1972,">0") -> 37481.962
A5: avg down day | B5: =AVERAGEIF('Daily PnL Log'!$J$3:$J$1972,"<0") -> -29647.7
A7: EV | B7: =(B4*B1)+(B5*B2) -> 7094.26
A8: annualized EV | B8: =B7*251 -> 1780659.3
A11: Column1 | B11: soybeans | C11: meal | D11: oil | E11: corn | F11: wheat | G11: kc
A12: % days positive | B12: =COUNTIF('Daily PnL Log'!$C$3:$C$1972,">0")/COUNT('Daily PnL Log'!$C$3:$C$1972) -> 0.50687023 | C12: =COUNTIF('Daily PnL Log'!$D$3:$D$1972,">0")/COUNT('Daily PnL Log'!$D$3:$D$1972) -> 0.49694656 | D12: =COUNTIF('Daily PnL Log'!$E$3:$E$1972,">0")/COUNT('Daily PnL Log'!$E$3:$E$1972) -> 0.37022901 | E12: =COUNTIF('Daily PnL Log'!$F$3:$F$1972,">0")/COUNT('Daily PnL Log'!$F$3:$F$1972) -> 0.50458015 | F12: =COUNTIF('Daily PnL Log'!$G$3:$G$1972,">0")/COUNT('Daily PnL Log'!$G$3:$G$1972) -> 0.51221374 | G12: =COUNTIF('Daily PnL Log'!$H$3:$H$1972,">0")/COUNTIFS('Daily PnL Log'!$H$3:$H$1972,"<>0",'Daily PnL Log'!$H$3:$H$1972,"<>") -> 0.46449704
A13: % days negative | B13: =COUNTIF('Daily PnL Log'!$C$3:$C$1972,"<0")/COUNT('Daily PnL Log'!$C$3:$C$1972) -> 0.49312977 | C13: =COUNTIF('Daily PnL Log'!$D$3:$D$1972,"<0")/COUNT('Daily PnL Log'!$D$3:$D$1972) -> 0.50305344 | D13: =COUNTIF('Daily PnL Log'!$E$3:$E$1972,"<0")/COUNT('Daily PnL Log'!$E$3:$E$1972) -> 0.3519084 | E13: =COUNTIF('Daily PnL Log'!$F$3:$F$1972,"<0")/COUNT('Daily PnL Log'!$F$3:$F$1972) -> 0.49541985 | F13: =COUNTIF('Daily PnL Log'!$G$3:$G$1972,"<0")/COUNT('Daily PnL Log'!$G$3:$G$1972) -> 0.48778626 | G13: =COUNTIF('Daily PnL Log'!$H$3:$H$1972,"<0")/COUNTIFS('Daily PnL Log'!$H$3:$H$1972,"<>0",'Daily PnL Log'!$H$3:$H$1972,"<>") -> 0.53550296
A15: avg up day | B15: =AVERAGEIF('Daily PnL Log'!$C$3:$C$1972,">0") -> 24015.196 | C15: =AVERAGEIF('Daily PnL Log'!$D$3:$D$1972,">0") -> 15836.107 | D15: =AVERAGEIF('Daily PnL Log'!$E$3:$E$1972,">0") -> 5530.9394 | E15: =AVERAGEIF('Daily PnL Log'!$F$3:$F$1972,">0") -> 14299.358 | F15: =AVERAGEIF('Daily PnL Log'!$G$3:$G$1972,">0") -> 14680.236 | G15: =AVERAGEIF('Daily PnL Log'!$H$3:$H$1972,">0") -> 4618.4217
A16: avg down day | B16: =AVERAGEIF('Daily PnL Log'!$C$3:$C$1972,"<0") -> -15903.896 | C16: =AVERAGEIF('Daily PnL Log'!$D$3:$D$1972,"<0") -> -12865.121 | D16: =AVERAGEIF('Daily PnL Log'!$E$3:$E$1972,"<0") -> -6986.604 | E16: =AVERAGEIF('Daily PnL Log'!$F$3:$F$1972,"<0") -> -13323.445 | F16: =AVERAGEIF('Daily PnL Log'!$G$3:$G$1972,"<0") -> -13104.973 | G16: =AVERAGEIF('Daily PnL Log'!$H$3:$H$1972,"<0") -> -4038.4796
A18: EV | B18: =(B15*B12)+(B16*B13) -> 4329.9032 | C18: =(C15*C12)+(C16*C13) -> 1397.8556 | D18: =(D15*D12)+(D16*D13) -> -410.93043 | E18: =(E15*E12)+(E16*E13) -> 614.47305 | F18: =(F15*F12)+(F16*F13) -> 1126.9928 | G18: =(G15*G12)+(G16*G13) -> -17.374556
A19: annualized EV | B19: =B18*251 -> 1086805.7 | C19: =C18*251 -> 350861.77 | D19: =D18*251 -> -103143.54 | E19: =E18*251 -> 154232.74 | F19: =F18*251 -> 282875.2 | G19: =G18*251 -> -4361.0136
A23: OC Notional | B23: 7500000
A24: Net Liq | B24: .
A25: Cash | B25: 500000
A26: Energies TE | B26: 0
A27: Expense | B27: -140000
B28: =SUM(B23:B27) -> 7860000
A30: expiry | B30: 45828
A31: int | B31: 0.0395
A32: dte | B32: =B30-TODAY() -> -244
A33: daily rate | B33: =(B31/365)*B32 -> -0.026405479
A35: int | B35: =B33*B28 -> -207547.07
A36: daily int | B36: =B35/B32 -> 850.60274
A38: itm prem | B38: 58.165
A39: parity | B39: =B38*B33 -> -1.5358747

Sheet Daily PnL Log
B1: TOTALS | C1: =SUM(Table5[Beans]) -> 5672173.2 | D1: =SUM(Table5[Meal]) -> 1831190.9 | E1: =SUM(Table5[Oil]) -> -538318.86 | F1: =SUM(Table5[Corn]) -> 804959.7 | G1: =SUM(Table5[Wheat]) -> 1476360.6 | H1: =SUM(Table5[KC Wheat]) -> -11745.2 | I1: =SUM(Table5[Energies]) -> 58860.25 | J1: =SUM(Table5[Total PnL]) -> 9293480.6 | K1: =SUM(Table5[Commissions]) -> -161438.06 | L1: =SUM(Table5[Clr/brk fees]) -> -988783.83 | M1: =SUM(Table5[Total Fees]) -> -1150221.9 | N1: =SUM(Table5[Net PnL]) -> 8143258.7 | W1: =AVERAGE(Table5[Margin]) -> 677503.86 | X1: =SUM(Table5[RoM]) -> 11.832013 | Y1: =SUM(Table5[Expenses]) -> -1290401.8 | Z1: =SUM(Table5[Int]) -> 442465.41 | AA1: =SUM(Table5[Distributions]) -> -5977310.9 | AB1: =SUM(Table5[Bonuses]) -> -200825.87
A2: Month | B2: Date | C2: Beans | D2: Meal | E2: Oil | F2: Corn | G2: Wheat | H2: KC Wheat | I2: Energies | J2: Total PnL | K2: Commissions | L2: Clr/brk fees | M2: Total Fees | N2: Net PnL | O2: Cum Beans | P2: Cum Meal | Q2: Cum Oil | R2: Cum Corn | S2: Cum Wheat | T2: Cum KC | U2: Cum Brent | V2: Cum PnL | W2: Margin | X2: RoM | Y2: Expenses | Z2: Int | AA2: Distributions | AB2: Bonuses | AC2: Net Liq
A3: =TEXT(B3,"mmm") -> Dec | B3: 44166 | C3: 26392 | D3: -6809 | E3: 16996 | F3: 51822 | G3: -8504 | H3: -453 | I3: 0 | J3: =IF(SUM(C3:I3)=0,"",SUM(C3:I3)) -> 79444 | K3: -343 | L3: -789 | M3: =IF(SUM(K3:L3)=0,"",SUM(K3:L3)) -> -1132 | N3: =IFERROR(J3+M3,"") -> 78312 | O3: =Table5[[#This Row],[Beans]] -> 26392 | P3: =Table5[[#This Row],[Meal]] -> -6809 | Q3: =Table5[[#This Row],[Oil]] -> 16996 | R3: =Table5[[#This Row],[Corn]] -> 51822 | S3: =Table5[[#This Row],[Wheat]] -> -8504 | T3: =Table5[[#This Row],[KC Wheat]] -> -453 | U3: =Table5[[#This Row],[Energies]] -> 0 | V3: =N3 -> 78312 | W3: 511504 | X3: =IFERROR(N3/W3,"") -> 0.15310144 | Y3: -4534.44 | AC3: 514915
A4: =TEXT(B4,"mmm") -> Dec | B4: 44167 | C4: -34672 | D4: -2480 | E4: 3917 | F4: -46548 | G4: 18015 | H4: 4023 | I4: 0 | J4: =IF(SUM(C4:I4)=0,"",SUM(C4:I4)) -> -57745 | K4: -201.2 | L4: -461.86 | M4: =IF(SUM(K4:L4)=0,"",SUM(K4:L4)) -> -663.06 | N4: =IFERROR(J4+M4,"") -> -58408.06 | O4: =IF(Table5[[#This Row],[Beans]]="","",O3+Table5[[#This Row],[Beans]]) -> -8280 | P4: =IF(Table5[[#This Row],[Meal]]="","",P3+Table5[[#This Row],[Meal]]) -> -9289 | Q4: =IF(Table5[[#This Row],[Oil]]="","",Q3+Table5[[#This Row],[Oil]]) -> 20913 | R4: =IF(Table5[[#This Row],[Corn]]="","",R3+Table5[[#This Row],[Corn]]) -> 5274 | S4: =IF(Table5[[#This Row],[Wheat]]="","",S3+Table5[[#This Row],[Wheat]]) -> 9511 | T4: =IF(Table5[[#This Row],[KC Wheat]]="","",T3+Table5[[#This Row],[KC Wheat]]) -> 3570 | U4: =IF(Table5[[#This Row],[Energies]]="","",U3+Table5[[#This Row],[Energies]]) -> 0 | V4: =IF(N4<>"",IFERROR(V3+N4,""),"") -> 19903.94 | W4: 535156 | X4: =IFERROR(N4/W4,"") -> -0.10914212 | AC4: 485194.5
A5: =TEXT(B5,"mmm") -> Dec | B5: 44168 | C5: -4247 | D5: 13770 | E5: -301 | F5: -21998 | G5: 600.2 | H5: -752 | I5: 0 | J5: =IF(SUM(C5:I5)=0,"",SUM(C5:I5)) -> -12927.8 | K5: -110.1 | L5: -253.23 | M5: =IF(SUM(K5:L5)=0,"",SUM(K5:L5)) -> -363.33 | N5: =IFERROR(J5+M5,"") -> -13291.13 | O5: =IF(Table5[[#This Row],[Beans]]="","",O4+Table5[[#This Row],[Beans]]) -> -12527 | P5: =IF(Table5[[#This Row],[Meal]]="","",P4+Table5[[#This Row],[Meal]]) -> 4481 | Q5: =IF(Table5[[#This Row],[Oil]]="","",Q4+Table5[[#This Row],[Oil]]) -> 20612 | R5: =IF(Table5[[#This Row],[Corn]]="","",R4+Table5[[#This Row],[Corn]]) -> -16724 | S5: =IF(Table5[[#This Row],[Wheat]]="","",S4+Table5[[#This Row],[Wheat]]) -> 10111.2 | T5: =IF(Table5[[#This Row],[KC Wheat]]="","",T4+Table5[[#This Row],[KC Wheat]]) -> 2818 | U5: =IF(Table5[[#This Row],[Energies]]="","",U4+Table5[[#This Row],[Energies]]) -> 0 | V5: =IF(N5<>"",IFERROR(V4+N5,""),"") -> 6612.81 | W5: 537434 | X5: =IFERROR(N5/W5,"") -> -0.02473072 | AC5: 450137.72
A6: =TEXT(B6,"mmm") -> Dec | B6: 44169 | C6: -2523 | D6: -2071 | E6: -9040 | F6: 85116 | G6: -8326 | H6: -1175 | I6: 0 | J6: =IF(SUM(C6:I6)=0,"",SUM(C6:I6)) -> 61981 | K6: -229 | L6: -512.67 | M6: =IF(SUM(K6:L6)=0,"",SUM(K6:L6)) -> -741.67 | N6: =IFERROR(J6+M6,"") -> 61239.33 | O6: =IF(Table5[[#This Row],[Beans]]="","",O5+Table5[[#This Row],[Beans]]) -> -15050 | P6: =IF(Table5[[#This Row],[Meal]]="","",P5+Table5[[#This Row],[Meal]]) -> 2410 | Q6: =IF(Table5[[#This Row],[Oil]]="","",Q5+Table5[[#This Row],[Oil]]) -> 11572 | R6: =IF(Table5[[#This Row],[Corn]]="","",R5+Table5[[#This Row],[Corn]]) -> 68392 | S6: =IF(Table5[[#This Row],[Wheat]]="","",S5+Table5[[#This Row],[Wheat]]) -> 1785.2 | T6: =IF(Table5[[#This Row],[KC Wheat]]="","",T5+Table5[[#This Row],[KC Wheat]]) -> 1643 | U6: =IF(Table5[[#This Row],[Energies]]="","",U5+Table5[[#This Row],[Energies]]) -> 0 | V6: =IF(N6<>"",IFERROR(V5+N6,""),"") -> 67852.14 | W6: 502836 | X6: =IFERROR(N6/W6,"") -> 0.12178788 | AC6: 507061.65
A7: =TEXT(B7,"mmm") -> Dec | B7: 44172 | C7: -4397 | D7: -22464 | E7: -4352 | F7: -20784 | G7: 9686 | H7: -266 | I7: 0 | J7: =IF(SUM(C7:I7)=0,"",SUM(C7:I7)) -> -42577 | K7: -173.9 | L7: -399.97 | M7: =IF(SUM(K7:L7)=0,"",SUM(K7:L7)) -> -573.87 | N7: =IFERROR(J7+M7,"") -> -43150.87 | O7: =IF(Table5[[#This Row],[Beans]]="","",O6+Table5[[#This Row],[Beans]]) -> -19447 | P7: =IF(Table5[[#This Row],[Meal]]="","",P6+Table5[[#This Row],[Meal]]) -> -20054 | Q7: =IF(Table5[[#This Row],[Oil]]="","",Q6+Table5[[#This Row],[Oil]]) -> 7220 | R7: =IF(Table5[[#This Row],[Corn]]="","",R6+Table5[[#This Row],[Corn]]) -> 47608 | S7: =IF(Table5[[#This Row],[Wheat]]="","",S6+Table5[[#This Row],[Wheat]]) -> 11471.2 | T7: =IF(Table5[[#This Row],[KC Wheat]]="","",T6+Table5[[#This Row],[KC Wheat]]) -> 1377 | U7: =IF(Table5[[#This Row],[Energies]]="","",U6+Table5[[#This Row],[Energies]]) -> 0 | V7: =IF(N7<>"",IFERROR(V6+N7,""),"") -> 24701.27 | W7: 527603 | X7: =IFERROR(N7/W7,"") -> -0.081786627 | AC7: 496410.78
A8: =TEXT(B8,"mmm") -> Dec | B8: 44173 | C8: 24437 | D8: -12518 | E8: 3376 | F8: 12578 | G8: -5257 | H8: 143.6 | I8: 0 | J8: =IF(SUM(C8:I8)=0,"",SUM(C8:I8)) -> 22759.6 | K8: -221 | L8: -504 | M8: =IF(SUM(K8:L8)=0,"",SUM(K8:L8)) -> -725 | N8: =IFERROR(J8+M8,"") -> 22034.6 | O8: =IF(Table5[[#This Row],[Beans]]="","",O7+Table5[[#This Row],[Beans]]) -> 4990 | P8: =IF(Table5[[#This Row],[Meal]]="","",P7+Table5[[#This Row],[Meal]]) -> -32572 | Q8: =IF(Table5[[#This Row],[Oil]]="","",Q7+Table5[[#This Row],[Oil]]) -> 10596 | R8: =IF(Table5[[#This Row],[Corn]]="","",R7+Table5[[#This Row],[Corn]]) -> 60186 | S8: =IF(Table5[[#This Row],[Wheat]]="","",S7+Table5[[#This Row],[Wheat]]) -> 6214.2 | T8: =IF(Table5[[#This Row],[KC Wheat]]="","",T7+Table5[[#This Row],[KC Wheat]]) -> 1520.6 | U8: =IF(Table5[[#This Row],[Energies]]="","",U7+Table5[[#This Row],[Energies]]) -> 0 | V8: =IF(N8<>"",IFERROR(V7+N8,""),"") -> 46735.87 | W8: 537111 | X8: =IFERROR(N8/W8,"") -> 0.041024295 | AC8: 511167.51
A9: =TEXT(B9,"mmm") -> Dec | B9: 44174 | C9: -13534.5 | D9: 13236.5 | E9: 5410.5 | F9: -265 | G9: -3936.1 | H9: 3708 | I9: 0 | J9: =IF(SUM(C9:I9)=0,"",SUM(C9:I9)) -> 4619.4 | K9: -225 | L9: -518 | M9: =IF(SUM(K9:L9)=0,"",SUM(K9:L9)) -> -743 | N9: =IFERROR(J9+M9,"") -> 3876.4 | O9: =IF(Table5[[#This Row],[Beans]]="","",O8+Table5[[#This Row],[Beans]]) -> -8544.5 | P9: =IF(Table5[[#This Row],[Meal]]="","",P8+Table5[[#This Row],[Meal]]) -> -19335.5 | Q9: =IF(Table5[[#This Row],[Oil]]="","",Q8+Table5[[#This Row],[Oil]]) -> 16006.5 | R9: =IF(Table5[[#This Row],[Corn]]="","",R8+Table5[[#This Row],[Corn]]) -> 59921 | S9: =IF(Table5[[#This Row],[Wheat]]="","",S8+Table5[[#This Row],[Wheat]]) -> 2278.1 | T9: =IF(Table5[[#This Row],[KC Wheat]]="","",T8+Table5[[#This Row],[KC Wheat]]) -> 5228.6 | U9: =IF(Table5[[#This Row],[Energies]]="","",U8+Table5[[#This Row],[Energies]]) -> 0 | V9: =IF(N9<>"",IFERROR(V8+N9,""),"") -> 50612.27 | W9: 570452 | X9: =IFERROR(N9/W9,"") -> 0.0067953132 | Y9: -494.32 | AC9: 477770.02
A10: =TEXT(B10,"mmm") -> Dec | B10: 44175 | C10: 16649 | D10: -1085.7 | E10: 4059.7 | F10: 43227.7 | G10: 32150.9 | H10: 2123 | I10: 0 | J10: =IF(SUM(C10:I10)=0,"",SUM(C10:I10)) -> 97124.6 | K10: -365.8 | L10: -841 | M10: =IF(SUM(K10:L10)=0,"",SUM(K10:L10)) -> -1206.8 | N10: =IFERROR(J10+M10,"") -> 95917.8 | O10: =IF(Table5[[#This Row],[Beans]]="","",O9+Table5[[#This Row],[Beans]]) -> 8104.5 | P10: =IF(Table5[[#This Row],[Meal]]="","",P9+Table5[[#This Row],[Meal]]) -> -20421.2 | Q10: =IF(Table5[[#This Row],[Oil]]="","",Q9+Table5[[#This Row],[Oil]]) -> 20066.2 | R10: =IF(Table5[[#This Row],[Corn]]="","",R9+Table5[[#This Row],[Corn]]) -> 103148.7 | S10: =IF(Table5[[#This Row],[Wheat]]="","",S9+Table5[[#This Row],[Wheat]]) -> 34429 | T10: =IF(Table5[[#This Row],[KC Wheat]]="","",T9+Table5[[#This Row],[KC Wheat]]) -> 7351.6 | U10: =IF(Table5[[#This Row],[Energies]]="","",U9+Table5[[#This Row],[Energies]]) -> 0 | V10: =IF(N10<>"",IFERROR(V9+N10,""),"") -> 146530.07 | W10: 655764 | X10: =IFERROR(N10/W10,"") -> 0.14626878 | AC10: 593470.63
A11: =TEXT(B11,"mmm") -> Dec | B11: 44176 | C11: -39875 | D11: 17694.1 | E11: -4784.3 | F11: 3647.6 | G11: -18220.9 | H11: 1175 | I11: 0 | J11: =IF(SUM(C11:I11)=0,"",SUM(C11:I11)) -> -40363.5 | K11: -195.4 | L11: -449.03 | M11: =IF(SUM(K11:L11)=0,"",SUM(K11:L11)) -> -644.43 | N11: =IFERROR(J11+M11,"") -> -41007.93 | O11: =IF(Table5[[#This Row],[Beans]]="","",O10+Table5[[#This Row],[Beans]]) -> -31770.5 | P11: =IF(Table5[[#This Row],[Meal]]="","",P10+Table5[[#This Row],[Meal]]) -> -2727.1 | Q11: =IF(Table5[[#This Row],[Oil]]="","",Q10+Table5[[#This Row],[Oil]]) -> 15281.9 | R11: =IF(Table5[[#This Row],[Corn]]="","",R10+Table5[[#This Row],[Corn]]) -> 106796.3 | S11: =IF(Table5[[#This Row],[Wheat]]="","",S10+Table5[[#This Row],[Wheat]]) -> 16208.1 | T11: =IF(Table5[[#This Row],[KC Wheat]]="","",T10+Table5[[#This Row],[KC Wheat]]) -> 8526.6 | U11: =IF(Table5[[#This Row],[Energies]]="","",U10+Table5[[#This Row],[Energies]]) -> 0 | V11: =IF(N11<>"",IFERROR(V10+N11,""),"") -> 105522.14 | W11: 607150 | X11: =IFERROR(N11/W11,"") -> -0.067541678 | AC11: 560283.45
A12: =TEXT(B12,"mmm") -> Dec | B12: 44179 | C12: -40323 | D12: 13345 | E12: 2258 | F12: 20498 | G12: -22991 | H12: 2330 | I12: 0 | J12: =IF(SUM(C12:I12)=0,"",SUM(C12:I12)) -> -24883 | K12: -282.7 | L12: -650.21 | M12: =IF(SUM(K12:L12)=0,"",SUM(K12:L12)) -> -932.91 | N12: =IFERROR(J12+M12,"") -> -25815.91 | O12: =IF(Table5[[#This Row],[Beans]]="","",O11+Table5[[#This Row],[Beans]]) -> -72093.5 | P12: =IF(Table5[[#This Row],[Meal]]="","",P11+Table5[[#This Row],[Meal]]) -> 10617.9 | Q12: =IF(Table5[[#This Row],[Oil]]="","",Q11+Table5[[#This Row],[Oil]]) -> 17539.9 | R12: =IF(Table5[[#This Row],[Corn]]="","",R11+Table5[[#This Row],[Corn]]) -> 127294.3 | S12: =IF(Table5[[#This Row],[Wheat]]="","",S11+Table5[[#This Row],[Wheat]]) -> -6782.9 | T12: =IF(Table5[[#This Row],[KC Wheat]]="","",T11+Table5[[#This Row],[KC Wheat]]) -> 10856.6 | U12: =IF(Table5[[#This Row],[Energies]]="","",U11+Table5[[#This Row],[Energies]]) -> 0 | V12: =IF(N12<>"",IFERROR(V11+N12,""),"") -> 79706.23 | W12: 834837 | X12: =IFERROR(N12/W12,"") -> -0.030923294 | AC12: 530848
A13: =TEXT(B13,"mmm") -> Dec | B13: 44180 | C13: 23205 | D13: -2204 | E13: -8303 | F13: -3983 | G13: 11694 | H13: -1560 | I13: 0 | J13: =IF(SUM(C13:I13)=0,"",SUM(C13:I13)) -> 18849 | K13: -260 | L13: -598 | M13: =IF(SUM(K13:L13)=0,"",SUM(K13:L13)) -> -858 | N13: =IFERROR(J13+M13,"") -> 17991 | O13: =IF(Table5[[#This Row],[Beans]]="","",O12+Table5[[#This Row],[Beans]]) -> -48888.5 | P13: =IF(Table5[[#This Row],[Meal]]="","",P12+Table5[[#This Row],[Meal]]) -> 8413.9 | Q13: =IF(Table5[[#This Row],[Oil]]="","",Q12+Table5[[#This Row],[Oil]]) -> 9236.9 | R13: =IF(Table5[[#This Row],[Corn]]="","",R12+Table5[[#This Row],[Corn]]) -> 123311.3 | S13: =IF(Table5[[#This Row],[Wheat]]="","",S12+Table5[[#This Row],[Wheat]]) -> 4911.1 | T13: =IF(Table5[[#This Row],[KC Wheat]]="","",T12+Table5[[#This Row],[KC Wheat]]) -> 9296.6 | U13: =IF(Table5[[#This Row],[Energies]]="","",U12+Table5[[#This Row],[Energies]]) -> 0 | V13: =IF(N13<>"",IFERROR(V12+N13,""),"") -> 97697.23 | W13: 752056 | X13: =IFERROR(N13/W13,"") -> 0.023922421 | AC13: 564475.79
A14: =TEXT(B14,"mmm") -> Dec | B14: 44181 | C14: 52890 | D14: 56581 | E14: 14164 | F14: 14013 | G14: -5924 | H14: -352 | I14: 0 | J14: =IF(SUM(C14:I14)=0,"",SUM(C14:I14)) -> 131372 | K14: -584.3 | L14: -1343.89 | M14: =IF(SUM(K14:L14)=0,"",SUM(K14:L14)) -> -1928.19 | N14: =IFERROR(J14+M14,"") -> 129443.81 | O14: =IF(Table5[[#This Row],[Beans]]="","",O13+Table5[[#This Row],[Beans]]) -> 4001.5 | P14: =IF(Table5[[#This Row],[Meal]]="","",P13+Table5[[#This Row],[Meal]]) -> 64994.9 | Q14: =IF(Table5[[#This Row],[Oil]]="","",Q13+Table5[[#This Row],[Oil]]) -> 23400.9 | R14: =IF(Table5[[#This Row],[Corn]]="","",R13+Table5[[#This Row],[Corn]]) -> 137324.3 | S14: =IF(Table5[[#This Row],[Wheat]]="","",S13+Table5[[#This Row],[Wheat]]) -> -1012.9 | T14: =IF(Table5[[#This Row],[KC Wheat]]="","",T13+Table5[[#This Row],[KC Wheat]]) -> 8944.6 | U14: =IF(Table5[[#This Row],[Energies]]="","",U13+Table5[[#This Row],[Energies]]) -> 0 | V14: =IF(N14<>"",IFERROR(V13+N14,""),"") -> 227141.04 | W14: 577307 | X14: =IFERROR(N14/W14,"") -> 0.22422006 | Y14: -3901.88 | AC14: 698531.35
A15: =TEXT(B15,"mmm") -> Dec | B15: 44182 | C15: -24271 | D15: 39986 | E15: -5529 | F15: -19519 | G15: 6861 | H15: 1397 | I15: 0 | J15: =IF(SUM(C15:I15)=0,"",SUM(C15:I15)) -> -1075 | K15: -380.2 | L15: -873.92 | M15: =IF(SUM(K15:L15)=0,"",SUM(K15:L15)) -> -1254.12 | N15: =IFERROR(J15+M15,"") -> -2329.12 | O15: =IF(Table5[[#This Row],[Beans]]="","",O14+Table5[[#This Row],[Beans]]) -> -20269.5 | P15: =IF(Table5[[#This Row],[Meal]]="","",P14+Table5[[#This Row],[Meal]]) -> 104980.9 | Q15: =IF(Table5[[#This Row],[Oil]]="","",Q14+Table5[[#This Row],[Oil]]) -> 17871.9 | R15: =IF(Table5[[#This Row],[Corn]]="","",R14+Table5[[#This Row],[Corn]]) -> 117805.3 | S15: =IF(Table5[[#This Row],[Wheat]]="","",S14+Table5[[#This Row],[Wheat]]) -> 5848.1 | T15: =IF(Table5[[#This Row],[KC Wheat]]="","",T14+Table5[[#This Row],[KC Wheat]]) -> 10341.6 | U15: =IF(Table5[[#This Row],[Energies]]="","",U14+Table5[[#This Row],[Energies]]) -> 0 | V15: =IF(N15<>"",IFERROR(V14+N15,""),"") -> 224811.92 | W15: 537527 | X15: =IFERROR(N15/W15,"") -> -0.0043330289 | AC15: 657004.98
A16: =TEXT(B16,"mmm") -> Dec | B16: 44183 | C16: -21471 | D16: 30533 | E16: 7856 | F16: -32080 | G16: 7351 | H16: -1350 | I16: 0 | J16: =IF(SUM(C16:I16)=0,"",SUM(C16:I16)) -> -9161 | K16: -326.9 | L16: -751.412 | M16: =IF(SUM(K16:L16)=0,"",SUM(K16:L16)) -> -1078.312 | N16: =IFERROR(J16+M16,"") -> -10239.312 | O16: =IF(Table5[[#This Row],[Beans]]="","",O15+Table5[[#This Row],[Beans]]) -> -41740.5 | P16: =IF(Table5[[#This Row],[Meal]]="","",P15+Table5[[#This Row],[Meal]]) -> 135513.9 | Q16: =IF(Table5[[#This Row],[Oil]]="","",Q15+Table5[[#This Row],[Oil]]) -> 25727.9 | R16: =IF(Table5[[#This Row],[Corn]]="","",R15+Table5[[#This Row],[Corn]]) -> 85725.3 | S16: =IF(Table5[[#This Row],[Wheat]]="","",S15+Table5[[#This Row],[Wheat]]) -> 13199.1 | T16: =IF(Table5[[#This Row],[KC Wheat]]="","",T15+Table5[[#This Row],[KC Wheat]]) -> 8991.6 | U16: =IF(Table5[[#This Row],[Energies]]="","",U15+Table5[[#This Row],[Energies]]) -> 0 | V16: =IF(N16<>"",IFERROR(V15+N16,""),"") -> 214572.61 | W16: 518736 | X16: =IFERROR(N16/W16,"") -> -0.019738965 | AC16: 653197.41
A17: =TEXT(B17,"mmm") -> Dec | B17: 44186 | C17: -21412 | D17: 13892 | E17: -2974 | F17: -26606 | G17: 14291 | H17: -3024 | I17: 0 | J17: =IF(SUM(C17:I17)=0,"",SUM(C17:I17)) -> -25833 | K17: -299.3 | L17: -688.3 | M17: =IF(SUM(K17:L17)=0,"",SUM(K17:L17)) -> -987.6 | N17: =IFERROR(J17+M17,"") -> -26820.6 | O17: =IF(Table5[[#This Row],[Beans]]="","",O16+Table5[[#This Row],[Beans]]) -> -63152.5 | P17: =IF(Table5[[#This Row],[Meal]]="","",P16+Table5[[#This Row],[Meal]]) -> 149405.9 | Q17: =IF(Table5[[#This Row],[Oil]]="","",Q16+Table5[[#This Row],[Oil]]) -> 22753.9 | R17: =IF(Table5[[#This Row],[Corn]]="","",R16+Table5[[#This Row],[Corn]]) -> 59119.3 | S17: =IF(Table5[[#This Row],[Wheat]]="","",S16+Table5[[#This Row],[Wheat]]) -> 27490.1 | T17: =IF(Table5[[#This Row],[KC Wheat]]="","",T16+Table5[[#This Row],[KC Wheat]]) -> 5967.6 | U17: =IF(Table5[[#This Row],[Energies]]="","",U16+Table5[[#This Row],[Energies]]) -> 0 | V17: =IF(N17<>"",IFERROR(V16+N17,""),"") -> 187752.01 | W17: 469834 | X17: =IFERROR(N17/W17,"") -> -0.057085268 | AC17: 675021.31
A18: =TEXT(B18,"mmm") -> Dec | B18: 44187 | C18: 17925 | D18: 14454 | E18: 1426 | F18: -29368 | G18: 7148 | H18: 597 | I18: 0 | J18: =IF(SUM(C18:I18)=0,"",SUM(C18:I18)) -> 12182 | K18: -221.1 | L18: -508.53 | M18: =IF(SUM(K18:L18)=0,"",SUM(K18:L18)) -> -729.63 | N18: =IFERROR(J18+M18,"") -> 11452.37 | O18: =IF(Table5[[#This Row],[Beans]]="","",O17+Table5[[#This Row],[Beans]]) -> -45227.5 | P18: =IF(Table5[[#This Row],[Meal]]="","",P17+Table5[[#This Row],[Meal]]) -> 163859.9 | Q18: =IF(Table5[[#This Row],[Oil]]="","",Q17+Table5[[#This Row],[Oil]]) -> 24179.9 | R18: =IF(Table5[[#This Row],[Corn]]="","",R17+Table5[[#This Row],[Corn]]) -> 29751.3 | S18: =IF(Table5[[#This Row],[Wheat]]="","",S17+Table5[[#This Row],[Wheat]]) -> 34638.1 | T18: =IF(Table5[[#This Row],[KC Wheat]]="","",T17+Table5[[#This Row],[KC Wheat]]) -> 6564.6 | U18: =IF(Table5[[#This Row],[Energies]]="","",U17+Table5[[#This Row],[Energies]]) -> 0 | V18: =IF(N18<>"",IFERROR(V17+N18,""),"") -> 199204.38 | W18: 455131 | X18: =IFERROR(N18/W18,"") -> 0.025162799 | AC18: 674363.18
A19: =TEXT(B19,"mmm") -> Dec | B19: 44188 | C19: -7026 | D19: 3956 | E19: -6614 | F19: -54369 | G19: 4143 | H19: -2762 | I19: 0 | J19: =IF(SUM(C19:I19)=0,"",SUM(C19:I19)) -> -62672 | K19: -197.7 | L19: -454.71 | M19: =IF(SUM(K19:L19)=0,"",SUM(K19:L19)) -> -652.41 | N19: =IFERROR(J19+M19,"") -> -63324.41 | O19: =IF(Table5[[#This Row],[Beans]]="","",O18+Table5[[#This Row],[Beans]]) -> -52253.5 | P19: =IF(Table5[[#This Row],[Meal]]="","",P18+Table5[[#This Row],[Meal]]) -> 167815.9 | Q19: =IF(Table5[[#This Row],[Oil]]="","",Q18+Table5[[#This Row],[Oil]]) -> 17565.9 | R19: =IF(Table5[[#This Row],[Corn]]="","",R18+Table5[[#This Row],[Corn]]) -> -24617.7 | S19: =IF(Table5[[#This Row],[Wheat]]="","",S18+Table5[[#This Row],[Wheat]]) -> 38781.1 | T19: =IF(Table5[[#This Row],[KC Wheat]]="","",T18+Table5[[#This Row],[KC Wheat]]) -> 3802.6 | U19: =IF(Table5[[#This Row],[Energies]]="","",U18+Table5[[#This Row],[Energies]]) -> 0 | V19: =IF(N19<>"",IFERROR(V18+N19,""),"") -> 135879.97 | W19: 546574 | X19: =IFERROR(N19/W19,"") -> -0.11585697 | Y19: -2292 | AC19: 587264.77
A20: =TEXT(B20,"mmm") -> Dec | B20: 44189 | C20: -18575 | D20: 5413 | E20: -5209 | F20: 33404 | G20: 41.7 | H20: 232 | I20: 0 | J20: =IF(SUM(C20:I20)=0,"",SUM(C20:I20)) -> 15306.7 | K20: -1602.5 | L20: -2317.57 | M20: =IF(SUM(K20:L20)=0,"",SUM(K20:L20)) -> -3920.07 | N20: =IFERROR(J20+M20,"") -> 11386.63 | O20: =IF(Table5[[#This Row],[Beans]]="","",O19+Table5[[#This Row],[Beans]]) -> -70828.5 | P20: =IF(Table5[[#This Row],[Meal]]="","",P19+Table5[[#This Row],[Meal]]) -> 173228.9 | Q20: =IF(Table5[[#This Row],[Oil]]="","",Q19+Table5[[#This Row],[Oil]]) -> 12356.9 | R20: =IF(Table5[[#This Row],[Corn]]="","",R19+Table5[[#This Row],[Corn]]) -> 8786.3 | S20: =IF(Table5[[#This Row],[Wheat]]="","",S19+Table5[[#This Row],[Wheat]]) -> 38822.8 | T20: =IF(Table5[[#This Row],[KC Wheat]]="","",T19+Table5[[#This Row],[KC Wheat]]) -> 4034.6 | U20: =IF(Table5[[#This Row],[Energies]]="","",U19+Table5[[#This Row],[Energies]]) -> 0 | V20: =IF(N20<>"",IFERROR(V19+N20,""),"") -> 147266.6 | W20: 620318 | X20: =IFERROR(N20/W20,"") -> 0.018356117 | AC20: 636614.95
A21: =TEXT(B21,"mmm") -> Dec | B21: 44193 | C21: 1870 | D21: 4872 | E21: 2252 | F21: 27167 | G21: -5893 | H21: -448 | I21: 0 | J21: =IF(SUM(C21:I21)=0,"",SUM(C21:I21)) -> 29820 | K21: -207.8 | L21: -477.91 | M21: =IF(SUM(K21:L21)=0,"",SUM(K21:L21)) -> -685.71 | N21: =IFERROR(J21+M21,"") -> 29134.29 | O21: =IF(Table5[[#This Row],[Beans]]="","",O20+Table5[[#This Row],[Beans]]) -> -68958.5 | P21: =IF(Table5[[#This Row],[Meal]]="","",P20+Table5[[#This Row],[Meal]]) -> 178100.9 | Q21: =IF(Table5[[#This Row],[Oil]]="","",Q20+Table5[[#This Row],[Oil]]) -> 14608.9 | R21: =IF(Table5[[#This Row],[Corn]]="","",R20+Table5[[#This Row],[Corn]]) -> 35953.3 | S21: =IF(Table5[[#This Row],[Wheat]]="","",S20+Table5[[#This Row],[Wheat]]) -> 32929.8 | T21: =IF(Table5[[#This Row],[KC Wheat]]="","",T20+Table5[[#This Row],[KC Wheat]]) -> 3586.6 | U21: =IF(Table5[[#This Row],[Energies]]="","",U20+Table5[[#This Row],[Energies]]) -> 0 | V21: =IF(N21<>"",IFERROR(V20+N21,""),"") -> 176400.89 | W21: 638866 | X21: =IFERROR(N21/W21,"") -> 0.045603131 | AC21: 630630.74
A22: =TEXT(B22,"mmm") -> Dec | B22: 44194 | C22: -44586 | D22: 845 | E22: -5619 | F22: -104510 | G22: 4305 | H22: 1177 | I22: 0 | J22: =IF(SUM(C22:I22)=0,"",SUM(C22:I22)) -> -148388 | K22: -168.6 | L22: -387.06 | M22: =IF(SUM(K22:L22)=0,"",SUM(K22:L22)) -> -555.66 | N22: =IFERROR(J22+M22,"") -> -148943.66 | O22: =IF(Table5[[#This Row],[Beans]]="","",O21+Table5[[#This Row],[Beans]]) -> -113544.5 | P22: =IF(Table5[[#This Row],[Meal]]="","",P21+Table5[[#This Row],[Meal]]) -> 178945.9 | Q22: =IF(Table5[[#This Row],[Oil]]="","",Q21+Table5[[#This Row],[Oil]]) -> 8989.9 | R22: =IF(Table5[[#This Row],[Corn]]="","",R21+Table5[[#This Row],[Corn]]) -> -68556.7 | S22: =IF(Table5[[#This Row],[Wheat]]="","",S21+Table5[[#This Row],[Wheat]]) -> 37234.8 | T22: =IF(Table5[[#This Row],[KC Wheat]]="","",T21+Table5[[#This Row],[KC Wheat]]) -> 4763.6 | U22: =IF(Table5[[#This Row],[Energies]]="","",U21+Table5[[#This Row],[Energies]]) -> 0 | V22: =IF(N22<>"",IFERROR(V21+N22,""),"") -> 27457.228 | W22: 640145 | X22: =IFERROR(N22/W22,"") -> -0.23267175 | Y22: -3901.88 | AA22: -71274.25 | AC22: 498047.58
A23: =TEXT(B23,"mmm") -> Dec | B23: 44195 | C23: 1301 | D23: -25604 | E23: 15610 | F23: -14677 | G23: 22984 | H23: -639 | I23: 0 | J23: =IF(SUM(C23:I23)=0,"",SUM(C23:I23)) -> -1025 | K23: -211.4 | L23: -486.22 | M23: =IF(SUM(K23:L23)=0,"",SUM(K23:L23)) -> -697.62 | N23: =IFERROR(J23+M23,"") -> -1722.62 | O23: =IF(Table5[[#This Row],[Beans]]="","",O22+Table5[[#This Row],[Beans]]) -> -112243.5 | P23: =IF(Table5[[#This Row],[Meal]]="","",P22+Table5[[#This Row],[Meal]]) -> 153341.9 | Q23: =IF(Table5[[#This Row],[Oil]]="","",Q22+Table5[[#This Row],[Oil]]) -> 24599.9 | R23: =IF(Table5[[#This Row],[Corn]]="","",R22+Table5[[#This Row],[Corn]]) -> -83233.7 | S23: =IF(Table5[[#This Row],[Wheat]]="","",S22+Table5[[#This Row],[Wheat]]) -> 60218.8 | T23: =IF(Table5[[#This Row],[KC Wheat]]="","",T22+Table5[[#This Row],[KC Wheat]]) -> 4124.6 | U23: =IF(Table5[[#This Row],[Energies]]="","",U22+Table5[[#This Row],[Energies]]) -> 0 | V23: =IF(N23<>"",IFERROR(V22+N23,""),"") -> 25734.608 | W23: 619947 | X23: =IFERROR(N23/W23,"") -> -0.0027786569 | AC23: 517116.96
A24: =TEXT(B24,"mmm") -> Dec | B24: 44196 | C24: -14236 | D24: 18469 | E24: 16035 | F24: -86553 | G24: 23210 | H24: 6296 | I24: 0 | J24: =IF(SUM(C24:I24)=0,"",SUM(C24:I24)) -> -36779 | K24: -411.9 | L24: -947.37 | M24: =IF(SUM(K24:L24)=0,"",SUM(K24:L24)) -> -1359.27 | N24: =IFERROR(J24+M24,"") -> -38138.27 | O24: =IF(Table5[[#This Row],[Beans]]="","",O23+Table5[[#This Row],[Beans]]) -> -126479.5 | P24: =IF(Table5[[#This Row],[Meal]]="","",P23+Table5[[#This Row],[Meal]]) -> 171810.9 | Q24: =IF(Table5[[#This Row],[Oil]]="","",Q23+Table5[[#This Row],[Oil]]) -> 40634.9 | R24: =IF(Table5[[#This Row],[Corn]]="","",R23+Table5[[#This Row],[Corn]]) -> -169786.7 | S24: =IF(Table5[[#This Row],[Wheat]]="","",S23+Table5[[#This Row],[Wheat]]) -> 83428.8 | T24: =IF(Table5[[#This Row],[KC Wheat]]="","",T23+Table5[[#This Row],[KC Wheat]]) -> 10420.6 | U24: =IF(Table5[[#This Row],[Energies]]="","",U23+Table5[[#This Row],[Energies]]) -> 0 | V24: =IF(N24<>"",IFERROR(V23+N24,""),"") -> -12403.662 | W24: 571633 | X24: =IFERROR(N24/W24,"") -> -0.066718104 | AC24: 429540.44
A25: =TEXT(B25,"mmm") -> Jan | B25: 44200 | C25: 40106.2 | D25: -4651 | E25: -10541.7 | F25: 3772.2 | G25: 21673.7 | H25: -8256.9 | I25: 0 | J25: =IF(SUM(C25:I25)=0,"",SUM(C25:I25)) -> 42102.5 | K25: -220.4 | L25: -506.92 | M25: =IF(SUM(K25:L25)=0,"",SUM(K25:L25)) -> -727.32 | N25: =IFERROR(J25+M25,"") -> 41375.18 | O25: =IF(Table5[[#This Row],[Beans]]="","",O24+Table5[[#This Row],[Beans]]) -> -86373.3 | P25: =IF(Table5[[#This Row],[Meal]]="","",P24+Table5[[#This Row],[Meal]]) -> 167159.9 | Q25: =IF(Table5[[#This Row],[Oil]]="","",Q24+Table5[[#This Row],[Oil]]) -> 30093.2 | R25: =IF(Table5[[#This Row],[Corn]]="","",R24+Table5[[#This Row],[Corn]]) -> -166014.5 | S25: =IF(Table5[[#This Row],[Wheat]]="","",S24+Table5[[#This Row],[Wheat]]) -> 105102.5 | T25: =IF(Table5[[#This Row],[KC Wheat]]="","",T24+Table5[[#This Row],[KC Wheat]]) -> 2163.7 | U25: =IF(Table5[[#This Row],[Energies]]="","",U24+Table5[[#This Row],[Energies]]) -> 0 | V25: =IF(N25<>"",IFERROR(V24+N25,""),"") -> 28971.518 | W25: 574028 | X25: =IFERROR(N25/W25,"") -> 0.072078679 | Y25: -530.95 | AA25: -429540.44 | AC25: 86079.43
A26: =TEXT(B26,"mmm") -> Jan | B26: 44201 | C26: -3994.5 | D26: -1153.7 | E26: -23510.7 | F26: -13806.8 | G26: 45942.7 | H26: 1625.2 | I26: 0 | J26: =IF(SUM(C26:I26)=0,"",SUM(C26:I26)) -> 5102.2 | K26: -335.6 | L26: -771.88 | M26: =IF(SUM(K26:L26)=0,"",SUM(K26:L26)) -> -1107.48 | N26: =IFERROR(J26+M26,"") -> 3994.72 | O26: =IF(Table5[[#This Row],[Beans]]="","",O25+Table5[[#This Row],[Beans]]) -> -90367.8 | P26: =IF(Table5[[#This Row],[Meal]]="","",P25+Table5[[#This Row],[Meal]]) -> 166006.2 | Q26: =IF(Table5[[#This Row],[Oil]]="","",Q25+Table5[[#This Row],[Oil]]) -> 6582.5 | R26: =IF(Table5[[#This Row],[Corn]]="","",R25+Table5[[#This Row],[Corn]]) -> -179821.3 | S26: =IF(Table5[[#This Row],[Wheat]]="","",S25+Table5[[#This Row],[Wheat]]) -> 151045.2 | T26: =IF(Table5[[#This Row],[KC Wheat]]="","",T25+Table5[[#This Row],[KC Wheat]]) -> 3788.9 | U26: =IF(Table5[[#This Row],[Energies]]="","",U25+Table5[[#This Row],[Energies]]) -> 0 | V26: =IF(N26<>"",IFERROR(V25+N26,""),"") -> 32966.238 | W26: 505650 | X26: =IFERROR(N26/W26,"") -> 0.0079001681 | AC26: 62202.7
A27: =TEXT(B27,"mmm") -> Jan | B27: 44202 | C27: 6693.5 | D27: -5655.6 | E27: 22539.2 | F27: 22857.4 | G27: -1768.8 | H27: 7479.6 | I27: 0 | J27: =IF(SUM(C27:I27)=0,"",SUM(C27:I27)) -> 52145.3 | K27: -324.1 | L27: -745.43 | M27: =IF(SUM(K27:L27)=0,"",SUM(K27:L27)) -> -1069.53 | N27: =IFERROR(J27+M27,"") -> 51075.77 | O27: =IF(Table5[[#This Row],[Beans]]="","",O26+Table5[[#This Row],[Beans]]) -> -83674.3 | P27: =IF(Table5[[#This Row],[Meal]]="","",P26+Table5[[#This Row],[Meal]]) -> 160350.6 | Q27: =IF(Table5[[#This Row],[Oil]]="","",Q26+Table5[[#This Row],[Oil]]) -> 29121.7 | R27: =IF(Table5[[#This Row],[Corn]]="","",R26+Table5[[#This Row],[Corn]]) -> -156963.9 | S27: =IF(Table5[[#This Row],[Wheat]]="","",S26+Table5[[#This Row],[Wheat]]) -> 149276.4 | T27: =IF(Table5[[#This Row],[KC Wheat]]="","",T26+Table5[[#This Row],[KC Wheat]]) -> 11268.5 | U27: =IF(Table5[[#This Row],[Energies]]="","",U26+Table5[[#This Row],[Energies]]) -> 0 | V27: =IF(N27<>"",IFERROR(V26+N27,""),"") -> 84042.008 | W27: 633885 | X27: =IFERROR(N27/W27,"") -> 0.080575767 | AC27: 115572.92
A28: =TEXT(B28,"mmm") -> Jan | B28: 44203 | C28: 5089.3 | D28: -6030.9 | E28: -7999.4 | F28: -6418.3 | G28: -1716.8 | H28: 8477.3 | I28: 0 | J28: =IF(SUM(C28:I28)=0,"",SUM(C28:I28)) -> -8598.8 | K28: -336.2 | L28: -773.26 | M28: =IF(SUM(K28:L28)=0,"",SUM(K28:L28)) -> -1109.46 | N28: =IFERROR(J28+M28,"") -> -9708.26 | O28: =IF(Table5[[#This Row],[Beans]]="","",O27+Table5[[#This Row],[Beans]]) -> -78585 | P28: =IF(Table5[[#This Row],[Meal]]="","",P27+Table5[[#This Row],[Meal]]) -> 154319.7 | Q28: =IF(Table5[[#This Row],[Oil]]="","",Q27+Table5[[#This Row],[Oil]]) -> 21122.3 | R28: =IF(Table5[[#This Row],[Corn]]="","",R27+Table5[[#This Row],[Corn]]) -> -163382.2 | S28: =IF(Table5[[#This Row],[Wheat]]="","",S27+Table5[[#This Row],[Wheat]]) -> 147559.6 | T28: =IF(Table5[[#This Row],[KC Wheat]]="","",T27+Table5[[#This Row],[KC Wheat]]) -> 19745.8 | U28: =IF(Table5[[#This Row],[Energies]]="","",U27+Table5[[#This Row],[Energies]]) -> 0 | V28: =IF(N28<>"",IFERROR(V27+N28,""),"") -> 74333.748 | W28: 702318 | X28: =IFERROR(N28/W28,"") -> -0.013823168 | AC28: 146918.21
A29: =TEXT(B29,"mmm") -> Jan | B29: 44204 | C29: 11189.4 | D29: -451.2 | E29: 9589.1 | F29: 2755.3 | G29: -8017.4 | H29: -1840.8 | I29: 0 | J29: =IF(SUM(C29:I29)=0,"",SUM(C29:I29)) -> 13224.4 | K29: -331.2 | L29: -761.76 | M29: =IF(SUM(K29:L29)=0,"",SUM(K29:L29)) -> -1092.96 | N29: =IFERROR(J29+M29,"") -> 12131.44 | O29: =IF(Table5[[#This Row],[Beans]]="","",O28+Table5[[#This Row],[Beans]]) -> -67395.6 | P29: =IF(Table5[[#This Row],[Meal]]="","",P28+Table5[[#This Row],[Meal]]) -> 153868.5 | Q29: =IF(Table5[[#This Row],[Oil]]="","",Q28+Table5[[#This Row],[Oil]]) -> 30711.4 | R29: =IF(Table5[[#This Row],[Corn]]="","",R28+Table5[[#This Row],[Corn]]) -> -160626.9 | S29: =IF(Table5[[#This Row],[Wheat]]="","",S28+Table5[[#This Row],[Wheat]]) -> 139542.2 | T29: =IF(Table5[[#This Row],[KC Wheat]]="","",T28+Table5[[#This Row],[KC Wheat]]) -> 17905 | U29: =IF(Table5[[#This Row],[Energies]]="","",U28+Table5[[#This Row],[Energies]]) -> 0 | V29: =IF(N29<>"",IFERROR(V28+N29,""),"") -> 86465.188 | W29: 555070 | X29: =IFERROR(N29/W29,"") -> 0.021855694 | AC29: 109764
A30: =TEXT(B30,"mmm") -> Jan | B30: 44207 | C30: 13145.7 | D30: 13628.5 | E30: -8993 | F30: 30199.3 | G30: -16084.2 | H30: -32458 | I30: 0 | J30: =IF(SUM(C30:I30)=0,"",SUM(C30:I30)) -> -561.7 | K30: -443.9 | L30: -1020.97 | M30: =IF(SUM(K30:L30)=0,"",SUM(K30:L30)) -> -1464.87 | N30: =IFERROR(J30+M30,"") -> -2026.57 | O30: =IF(Table5[[#This Row],[Beans]]="","",O29+Table5[[#This Row],[Beans]]) -> -54249.9 | P30: =IF(Table5[[#This Row],[Meal]]="","",P29+Table5[[#This Row],[Meal]]) -> 167497 | Q30: =IF(Table5[[#This Row],[Oil]]="","",Q29+Table5[[#This Row],[Oil]]) -> 21718.4 | R30: =IF(Table5[[#This Row],[Corn]]="","",R29+Table5[[#This Row],[Corn]]) -> -130427.6 | S30: =IF(Table5[[#This Row],[Wheat]]="","",S29+Table5[[#This Row],[Wheat]]) -> 123458 | T30: =IF(Table5[[#This Row],[KC Wheat]]="","",T29+Table5[[#This Row],[KC Wheat]]) -> -14553 | U30: =IF(Table5[[#This Row],[Energies]]="","",U29+Table5[[#This Row],[Energies]]) -> 0 | V30: =IF(N30<>"",IFERROR(V29+N30,""),"") -> 84438.618 | W30: 579176 | X30: =IFERROR(N30/W30,"") -> -0.0034990573 | Y30: -1388.53 | AC30: 121639.38
A31: =TEXT(B31,"mmm") -> Jan | B31: 44208 | C31: -14581.6 | D31: 9798.6 | E31: 1109.5 | F31: 11221.4 | G31: 65911.7 | H31: -9798.5 | I31: 0 | J31: =IF(SUM(C31:I31)=0,"",SUM(C31:I31)) -> 63661.1 | K31: -392.7 | L31: -903.21 | M31: =IF(SUM(K31:L31)=0,"",SUM(K31:L31)) -> -1295.91 | N31: =IFERROR(J31+M31,"") -> 62365.19 | O31: =IF(Table5[[#This Row],[Beans]]="","",O30+Table5[[#This Row],[Beans]]) -> -68831.5 | P31: =IF(Table5[[#This Row],[Meal]]="","",P30+Table5[[#This Row],[Meal]]) -> 177295.6 | Q31: =IF(Table5[[#This Row],[Oil]]="","",Q30+Table5[[#This Row],[Oil]]) -> 22827.9 | R31: =IF(Table5[[#This Row],[Corn]]="","",R30+Table5[[#This Row],[Corn]]) -> -119206.2 | S31: =IF(Table5[[#This Row],[Wheat]]="","",S30+Table5[[#This Row],[Wheat]]) -> 189369.7 | T31: =IF(Table5[[#This Row],[KC Wheat]]="","",T30+Table5[[#This Row],[KC Wheat]]) -> -24351.5 | U31: =IF(Table5[[#This Row],[Energies]]="","",U30+Table5[[#This Row],[Energies]]) -> 0 | V31: =IF(N31<>"",IFERROR(V30+N31,""),"") -> 146803.81 | W31: 593466 | X31: =IFERROR(N31/W31,"") -> 0.10508637 | Y31: -125 | AC31: -54154.03
A32: =TEXT(B32,"mmm") -> Jan | B32: 44209 | C32: 55269.3 | D32: -16230 | E32: -652.3 | F32: 10492.2 | G32: 24637 | H32: -1563.5 | I32: 0 | J32: =IF(SUM(C32:I32)=0,"",SUM(C32:I32)) -> 71952.7 | K32: -830.5 | L32: -1910.12 | M32: =IF(SUM(K32:L32)=0,"",SUM(K32:L32)) -> -2740.62 | N32: =IFERROR(J32+M32,"") -> 69212.08 | O32: =IF(Table5[[#This Row],[Beans]]="","",O31+Table5[[#This Row],[Beans]]) -> -13562.2 | P32: =IF(Table5[[#This Row],[Meal]]="","",P31+Table5[[#This Row],[Meal]]) -> 161065.6 | Q32: =IF(Table5[[#This Row],[Oil]]="","",Q31+Table5[[#This Row],[Oil]]) -> 22175.6 | R32: =IF(Table5[[#This Row],[Corn]]="","",R31+Table5[[#This Row],[Corn]]) -> -108714 | S32: =IF(Table5[[#This Row],[Wheat]]="","",S31+Table5[[#This Row],[Wheat]]) -> 214006.7 | T32: =IF(Table5[[#This Row],[KC Wheat]]="","",T31+Table5[[#This Row],[KC Wheat]]) -> -25915 | U32: =IF(Table5[[#This Row],[Energies]]="","",U31+Table5[[#This Row],[Energies]]) -> 0 | V32: =IF(N32<>"",IFERROR(V31+N32,""),"") -> 216015.89 | W32: 418646 | X32: =IFERROR(N32/W32,"") -> 0.16532364 | AC32: 257737.1
A33: =TEXT(B33,"mmm") -> Jan | B33: 44210 | C33: -9365.9 | D33: 5512.2 | E33: 5121.6 | F33: 20474.8 | G33: -9101.9 | H33: -5077.9 | I33: 0 | J33: =IF(SUM(C33:I33)=0,"",SUM(C33:I33)) -> 7562.9 | K33: -418.3 | L33: -961.25 | M33: =IF(SUM(K33:L33)=0,"",SUM(K33:L33)) -> -1379.55 | N33: =IFERROR(J33+M33,"") -> 6183.35 | O33: =IF(Table5[[#This Row],[Beans]]="","",O32+Table5[[#This Row],[Beans]]) -> -22928.1 | P33: =IF(Table5[[#This Row],[Meal]]="","",P32+Table5[[#This Row],[Meal]]) -> 166577.8 | Q33: =IF(Table5[[#This Row],[Oil]]="","",Q32+Table5[[#This Row],[Oil]]) -> 27297.2 | R33: =IF(Table5[[#This Row],[Corn]]="","",R32+Table5[[#This Row],[Corn]]) -> -88239.2 | S33: =IF(Table5[[#This Row],[Wheat]]="","",S32+Table5[[#This Row],[Wheat]]) -> 204904.8 | T33: =IF(Table5[[#This Row],[KC Wheat]]="","",T32+Table5[[#This Row],[KC Wheat]]) -> -30992.9 | U33: =IF(Table5[[#This Row],[Energies]]="","",U32+Table5[[#This Row],[Energies]]) -> 0 | V33: =IF(N33<>"",IFERROR(V32+N33,""),"") -> 222199.24 | W33: 405870 | X33: =IFERROR(N33/W33,"") -> 0.015234804 | AC33: 219076.3
A34: =TEXT(B34,"mmm") -> Jan | B34: 44211 | C34: 25955 | D34: -18377 | E34: 2888 | F34: -4839.5 | G34: -13182.5 | H34: 7131.5 | I34: 0 | J34: =IF(SUM(C34:I34)=0,"",SUM(C34:I34)) -> -424.5 | K34: -174.4 | L34: -400.67 | M34: =IF(SUM(K34:L34)=0,"",SUM(K34:L34)) -> -575.07 | N34: =IFERROR(J34+M34,"") -> -999.57 | O34: =IF(Table5[[#This Row],[Beans]]="","",O33+Table5[[#This Row],[Beans]]) -> 3026.9 | P34: =IF(Table5[[#This Row],[Meal]]="","",P33+Table5[[#This Row],[Meal]]) -> 148200.8 | Q34: =IF(Table5[[#This Row],[Oil]]="","",Q33+Table5[[#This Row],[Oil]]) -> 30185.2 | R34: =IF(Table5[[#This Row],[Corn]]="","",R33+Table5[[#This Row],[Corn]]) -> -93078.7 | S34: =IF(Table5[[#This Row],[Wheat]]="","",S33+Table5[[#This Row],[Wheat]]) -> 191722.3 | T34: =IF(Table5[[#This Row],[KC Wheat]]="","",T33+Table5[[#This Row],[KC Wheat]]) -> -23861.4 | U34: =IF(Table5[[#This Row],[Energies]]="","",U33+Table5[[#This Row],[Energies]]) -> 0 | V34: =IF(N34<>"",IFERROR(V33+N34,""),"") -> 221199.67 | W34: 424968 | X34: =IFERROR(N34/W34,"") -> -0.0023521065 | AC34: 262855.48
A35: =TEXT(B35,"mmm") -> Jan | B35: 44215 | C35: 19006.6 | D35: -26003.3 | E35: 5702.8 | F35: 11697.2 | G35: 3653.5 | H35: -8.9 | I35: 0 | J35: =IF(SUM(C35:I35)=0,"",SUM(C35:I35)) -> 14047.9 | K35: -347 | L35: -797.05 | M35: =IF(SUM(K35:L35)=0,"",SUM(K35:L35)) -> -1144.05 | N35: =IFERROR(J35+M35,"") -> 12903.85 | O35: =IF(Table5[[#This Row],[Beans]]="","",O34+Table5[[#This Row],[Beans]]) -> 22033.5 | P35: =IF(Table5[[#This Row],[Meal]]="","",P34+Table5[[#This Row],[Meal]]) -> 122197.5 | Q35: =IF(Table5[[#This Row],[Oil]]="","",Q34+Table5[[#This Row],[Oil]]) -> 35888 | R35: =IF(Table5[[#This Row],[Corn]]="","",R34+Table5[[#This Row],[Corn]]) -> -81381.5 | S35: =IF(Table5[[#This Row],[Wheat]]="","",S34+Table5[[#This Row],[Wheat]]) -> 195375.8 | T35: =IF(Table5[[#This Row],[KC Wheat]]="","",T34+Table5[[#This Row],[KC Wheat]]) -> -23870.3 | U35: =IF(Table5[[#This Row],[Energies]]="","",U34+Table5[[#This Row],[Energies]]) -> 0 | V35: =IF(N35<>"",IFERROR(V34+N35,""),"") -> 234103.52 | W35: 419208 | X35: =IFERROR(N35/W35,"") -> 0.030781497 | Y35: -4134.38 | AC35: 275659.68
A36: =TEXT(B36,"mmm") -> Jan | B36: 44216 | C36: -2612.5 | D36: 9961.5 | E36: 7842.6 | F36: -5937.8 | G36: 24721.8 | H36: 3396.5 | I36: 0 | J36: =IF(SUM(C36:I36)=0,"",SUM(C36:I36)) -> 37372.1 | K36: -307.9 | L36: -706.61 | M36: =IF(SUM(K36:L36)=0,"",SUM(K36:L36)) -> -1014.51 | N36: =IFERROR(J36+M36,"") -> 36357.59 | O36: =IF(Table5[[#This Row],[Beans]]="","",O35+Table5[[#This Row],[Beans]]) -> 19421 | P36: =IF(Table5[[#This Row],[Meal]]="","",P35+Table5[[#This Row],[Meal]]) -> 132159 | Q36: =IF(Table5[[#This Row],[Oil]]="","",Q35+Table5[[#This Row],[Oil]]) -> 43730.6 | R36: =IF(Table5[[#This Row],[Corn]]="","",R35+Table5[[#This Row],[Corn]]) -> -87319.3 | S36: =IF(Table5[[#This Row],[Wheat]]="","",S35+Table5[[#This Row],[Wheat]]) -> 220097.6 | T36: =IF(Table5[[#This Row],[KC Wheat]]="","",T35+Table5[[#This Row],[KC Wheat]]) -> -20473.8 | U36: =IF(Table5[[#This Row],[Energies]]="","",U35+Table5[[#This Row],[Energies]]) -> 0 | V36: =IF(N36<>"",IFERROR(V35+N36,""),"") -> 270461.11 | W36: 564346 | X36: =IFERROR(N36/W36,"") -> 0.064424289 | AC36: 319597.67
A37: =TEXT(B37,"mmm") -> Jan | B37: 44217 | C37: 9209.9 | D37: 2946.1 | E37: -12528.9 | F37: 23075 | G37: -27052.5 | H37: -5363.4 | I37: 0 | J37: =IF(SUM(C37:I37)=0,"",SUM(C37:I37)) -> -9713.8 | K37: -446.7 | L37: -1027.38 | M37: =IF(SUM(K37:L37)=0,"",SUM(K37:L37)) -> -1474.08 | N37: =IFERROR(J37+M37,"") -> -11187.88 | O37: =IF(Table5[[#This Row],[Beans]]="","",O36+Table5[[#This Row],[Beans]]) -> 28630.9 | P37: =IF(Table5[[#This Row],[Meal]]="","",P36+Table5[[#This Row],[Meal]]) -> 135105.1 | Q37: =IF(Table5[[#This Row],[Oil]]="","",Q36+Table5[[#This Row],[Oil]]) -> 31201.7 | R37: =IF(Table5[[#This Row],[Corn]]="","",R36+Table5[[#This Row],[Corn]]) -> -64244.3 | S37: =IF(Table5[[#This Row],[Wheat]]="","",S36+Table5[[#This Row],[Wheat]]) -> 193045.1 | T37: =IF(Table5[[#This Row],[KC Wheat]]="","",T36+Table5[[#This Row],[KC Wheat]]) -> -25837.2 | U37: =IF(Table5[[#This Row],[Energies]]="","",U36+Table5[[#This Row],[Energies]]) -> 0 | V37: =IF(N37<>"",IFERROR(V36+N37,""),"") -> 259273.23 | W37: 533459 | X37: =IFERROR(N37/W37,"") -> -0.020972333 | AC37: 330574.84
A38: =TEXT(B38,"mmm") -> Jan | B38: 44218 | C38: 23672.6 | D38: 87083.9 | E38: 9583.9 | F38: -23953.8 | G38: -18059.5 | H38: 358.9 | I38: 0 | J38: =IF(SUM(C38:I38)=0,"",SUM(C38:I38)) -> 78686 | K38: -1556.1 | L38: -2650.04 | M38: =IF(SUM(K38:L38)=0,"",SUM(K38:L38)) -> -4206.14 | N38: =IFERROR(J38+M38,"") -> 74479.86 | O38: =IF(Table5[[#This Row],[Beans]]="","",O37+Table5[[#This Row],[Beans]]) -> 52303.5 | P38: =IF(Table5[[#This Row],[Meal]]="","",P37+Table5[[#This Row],[Meal]]) -> 222189 | Q38: =IF(Table5[[#This Row],[Oil]]="","",Q37+Table5[[#This Row],[Oil]]) -> 40785.6 | R38: =IF(Table5[[#This Row],[Corn]]="","",R37+Table5[[#This Row],[Corn]]) -> -88198.1 | S38: =IF(Table5[[#This Row],[Wheat]]="","",S37+Table5[[#This Row],[Wheat]]) -> 174985.6 | T38: =IF(Table5[[#This Row],[KC Wheat]]="","",T37+Table5[[#This Row],[KC Wheat]]) -> -25478.3 | U38: =IF(Table5[[#This Row],[Energies]]="","",U37+Table5[[#This Row],[Energies]]) -> 0 | V38: =IF(N38<>"",IFERROR(V37+N38,""),"") -> 333753.09 | W38: 753463 | X38: =IFERROR(N38/W38,"") -> 0.098850056 | AC38: 391700.8
A39: =TEXT(B39,"mmm") -> Jan | B39: 44221 | C39: 3143.7 | D39: -1075.1 | E39: 2192.1 | F39: 38506.1 | G39: 4253.6 | H39: 2544.5 | I39: 0 | J39: =IF(SUM(C39:I39)=0,"",SUM(C39:I39)) -> 49564.9 | K39: -306 | L39: -703.8 | M39: =IF(SUM(K39:L39)=0,"",SUM(K39:L39)) -> -1009.8 | N39: =IFERROR(J39+M39,"") -> 48555.1 | O39: =IF(Table5[[#This Row],[Beans]]="","",O38+Table5[[#This Row],[Beans]]) -> 55447.2 | P39: =IF(Table5[[#This Row],[Meal]]="","",P38+Table5[[#This Row],[Meal]]) -> 221113.9 | Q39: =IF(Table5[[#This Row],[Oil]]="","",Q38+Table5[[#This Row],[Oil]]) -> 42977.7 | R39: =IF(Table5[[#This Row],[Corn]]="","",R38+Table5[[#This Row],[Corn]]) -> -49692 | S39: =IF(Table5[[#This Row],[Wheat]]="","",S38+Table5[[#This Row],[Wheat]]) -> 179239.2 | T39: =IF(Table5[[#This Row],[KC Wheat]]="","",T38+Table5[[#This Row],[KC Wheat]]) -> -22933.8 | U39: =IF(Table5[[#This Row],[Energies]]="","",U38+Table5[[#This Row],[Energies]]) -> 0 | V39: =IF(N39<>"",IFERROR(V38+N39,""),"") -> 382308.19 | W39: 658417 | X39: =IFERROR(N39/W39,"") -> 0.07374521 | Y39: -4497.85 | AC39: 462584.4
A40: =TEXT(B40,"mmm") -> Jan | B40: 44222 | C40: 26149.8 | D40: 16916.9 | E40: 21427.9 | F40: -10068.2 | G40: 12693.8 | H40: 9694.4 | I40: 0 | J40: =IF(SUM(C40:I40)=0,"",SUM(C40:I40)) -> 76814.6 | K40: -593 | L40: -1363.75 | M40: =IF(SUM(K40:L40)=0,"",SUM(K40:L40)) -> -1956.75 | N40: =IFERROR(J40+M40,"") -> 74857.85 | O40: =IF(Table5[[#This Row],[Beans]]="","",O39+Table5[[#This Row],[Beans]]) -> 81597 | P40: =IF(Table5[[#This Row],[Meal]]="","",P39+Table5[[#This Row],[Meal]]) -> 238030.8 | Q40: =IF(Table5[[#This Row],[Oil]]="","",Q39+Table5[[#This Row],[Oil]]) -> 64405.6 | R40: =IF(Table5[[#This Row],[Corn]]="","",R39+Table5[[#This Row],[Corn]]) -> -59760.2 | S40: =IF(Table5[[#This Row],[Wheat]]="","",S39+Table5[[#This Row],[Wheat]]) -> 191933 | T40: =IF(Table5[[#This Row],[KC Wheat]]="","",T39+Table5[[#This Row],[KC Wheat]]) -> -13239.4 | U40: =IF(Table5[[#This Row],[Energies]]="","",U39+Table5[[#This Row],[Energies]]) -> 0 | V40: =IF(N40<>"",IFERROR(V39+N40,""),"") -> 457166.04 | W40: 496721.9 | X40: =IFERROR(N40/W40,"") -> 0.15070374 | AC40: 496721.9
...

Sheet Yr 2026
A2: YTD PnL
A7: Trading PnL | B7: =J48 -> 519997.9
A8: Commissions | B8: =K48 -> -3060.63
A9: Exchange Fees | B9: =L48 -> -26182.65
A10: Expenses | B10: =Y48 -> -32464.34
A11: Interest | B11: =Z48 -> 470.85
A12: NET PNL | B12: =B7+(B8+B9+B10+B11) -> 458761.13
A14: Average Margin | B14: =W48 -> 674379.3
A15: RoM | B15: =B12/B14 -> 0.68027166
A16: Std Dev | B16: =X48 -> 0.13006777
A17: Sharpe | B17: =(B15-0.045)/B16 -> 4.884159
B48: TOTALS | C48: =SUM(C50:C297) -> 480151.7 | D48: =SUM(D50:D297) -> 82832.7 | E48: =SUM(E50:E297) -> 0 | F48: =SUM(F50:F297) -> -28301.8 | G48: =SUM(G50:G297) -> -14684.7 | H48: =SUM(H50:H297) -> 0 | I48: =SUM(I50:I297) -> 0 | J48: =SUM(J50:J297) -> 519997.9 | ... N48: =SUM(N50:N297) -> 490754.62 | W48: =AVERAGE(W50:W295) -> 674379.3 | X48: =_xlfn.STDEV.P(X50:X295) -> 0.13006777 | Y48: =SUM(Y50:Y295) -> -32464.34 | Z48: =SUM(Z50:Z295) -> 470.85 | AA48: =SUM(AA50:AA295) -> -262055.72 | AB48: =SUM(AB50:AB295) -> 0
A49: Month | B49: Date | C49: Beans | D49: Meal | E49: Oil | F49: Corn | G49: Wheat | H49: KC Wheat | I49: Brent | J49: Total PnL | K49: Commissions | L49: Clr/brk fees | M49: Total Fees | N49: Net PnL | O49: Cum Beans | P49: Cum Meal | Q49: Cum Oil | R49: Cum Corn | S49: Cum Wheat | T49: Cum KC | U49: Cum Brent | V49: Cum PnL | W49: Margin | X49: RoM | Y49: Expenses | Z49: Int | AA49: Distributions | AB49: Bonuses | AC49: Net Liq
A50: =TEXT(B50,"mmm") -> Jan | B50: ='Daily PnL Log'!B1281 -> 46024 | C50: ='Daily PnL Log'!C1281 -> 22511 | D50: ='Daily PnL Log'!D1281 -> -2103.6 | E50: ='Daily PnL Log'!E1281 -> 0 | F50: ='Daily PnL Log'!F1281 -> 6684.9 | G50: ='Daily PnL Log'!G1281 -> -5901.8 | H50: ='Daily PnL Log'!H1281 -> 0 | I50: ='Daily PnL Log'!I1281 -> 0 | ... N50: ='Daily PnL Log'!N1281 -> 20804.18 | O50: =C50 -> 22511 | P50: =D50 -> -2103.6 | Q50: =E50 -> 0 | R50: =F50 -> 6684.9 | S50: =G50 -> -5901.8 | T50: =H50 -> 0 | U50: =I50 -> 0 | V50: =SUM(O50:T50) -> 21190.5 | W50: =IF('Daily PnL Log'!W1281<>"",'Daily PnL Log'!W1281,"") -> 494970 | X50: =IF('Daily PnL Log'!X1281<>"",'Daily PnL Log'!X1281,"") -> 0.042031194 | Y50: =IF('Daily PnL Log'!Y1281<>"",'Daily PnL Log'!Y1281,"") | Z50: =IF('Daily PnL Log'!Z1281<>"",'Daily PnL Log'!Z1281,"") | AA50: =IF('Daily PnL Log'!AA1281<>"",'Daily PnL Log'!AA1281,"") | AB50: =IF('Daily PnL Log'!AB1281<>"",'Daily PnL Log'!AB1281,"") | AC50: =IF('Daily PnL Log'!AC1281<>"",'Daily PnL Log'!AC1281,"") -> 289426.9
A51: =TEXT(B51,"mmm") -> Jan | B51: ='Daily PnL Log'!B1282 -> 46027 | C51: ='Daily PnL Log'!C1282 -> 30643.6 | D51: ='Daily PnL Log'!D1282 -> -5802.9 | E51: ='Daily PnL Log'!E1282 -> 0 | F51: ='Daily PnL Log'!F1282 -> -2260.1 | G51: ='Daily PnL Log'!G1282 -> -19309.3 | H51: ='Daily PnL Log'!H1282 -> 0 | I51: ='Daily PnL Log'!I1282 -> 0 | ... N51: ='Daily PnL Log'!N1282 -> 2730.87 | O51: =IF(C51<>"",O50+C51,"") -> 53154.6 | P51: =IF(D51<>"",P50+D51,"") -> -7906.5 | Q51: =IF(E51<>"",Q50+E51,"") -> 0 | R51: =IF(F51<>"",R50+F51,"") -> 4424.8 | S51: =IF(G51<>"",S50+G51,"") -> -25211.1 | T51: =IF(H51<>"",T50+H51,"") -> 0 | U51: =IF(I51<>"",U50+I51,"") -> 0 | V51: =IF(J51<>"",V50+J51,"") -> 24461.8 | W51: =IF('Daily PnL Log'!W1282<>"",'Daily PnL Log'!W1282,"") -> 465552 | X51: =IF('Daily PnL Log'!X1282<>"",'Daily PnL Log'!X1282,"") -> 0.0058658753 | Y51: =IF('Daily PnL Log'!Y1282<>"",'Daily PnL Log'!Y1282,"") -> -5908.56 | Z51: =IF('Daily PnL Log'!Z1282<>"",'Daily PnL Log'!Z1282,"") | AA51: =IF('Daily PnL Log'!AA1282<>"",'Daily PnL Log'!AA1282,"") -> -262055.72 | AB51: =IF('Daily PnL Log'!AB1282<>"",'Daily PnL Log'!AB1282,"") | AC51: =IF('Daily PnL Log'!AC1282<>"",'Daily PnL Log'!AC1282,"") -> 53948.25
A52: =TEXT(B52,"mmm") -> Jan | B52: ='Daily PnL Log'!B1283 -> 46028 | C52: ='Daily PnL Log'!C1283 -> 12639.6 | D52: ='Daily PnL Log'!D1283 -> 5190.6 | E52: ='Daily PnL Log'!E1283 -> 0 | F52: ='Daily PnL Log'!F1283 -> 3803.4 | G52: ='Daily PnL Log'!G1283 -> -6787.1 | H52: ='Daily PnL Log'!H1283 -> 0 | I52: ='Daily PnL Log'!I1283 -> 0 | ... N52: ='Daily PnL Log'!N1283 -> 14244.29 | O52: =IF(C52<>"",O51+C52,"") -> 65794.2 | P52: =IF(D52<>"",P51+D52,"") -> -2715.9 | Q52: =IF(E52<>"",Q51+E52,"") -> 0 | R52: =IF(F52<>"",R51+F52,"") -> 8228.2 | S52: =IF(G52<>"",S51+G52,"") -> -31998.2 | T52: =IF(H52<>"",T51+H52,"") -> 0 | U52: =IF(I52<>"",U51+I52,"") -> 0 | V52: =IF(J52<>"",V51+J52,"") -> 39308.3 | W52: =IF('Daily PnL Log'!W1283<>"",'Daily PnL Log'!W1283,"") -> 504295 | X52: =IF('Daily PnL Log'!X1283<>"",'Daily PnL Log'!X1283,"") -> 0.028245947 | Y52: =IF('Daily PnL Log'!Y1283<>"",'Daily PnL Log'!Y1283,"") | Z52: =IF('Daily PnL Log'!Z1283<>"",'Daily PnL Log'!Z1283,"") | AA52: =IF('Daily PnL Log'!AA1283<>"",'Daily PnL Log'!AA1283,"") | AB52: =IF('Daily PnL Log'!AB1283<>"",'Daily PnL Log'!AB1283,"") | AC52: =IF('Daily PnL Log'!AC1283<>"",'Daily PnL Log'!AC1283,"") -> 74301.04
A53: =TEXT(B53,"mmm") -> Jan | B53: ='Daily PnL Log'!B1284 -> 46029 | C53: ='Daily PnL Log'!C1284 -> 25296.3 | D53: ='Daily PnL Log'!D1284 -> 11912.6 | E53: ='Daily PnL Log'!E1284 -> 0 | F53: ='Daily PnL Log'!F1284 -> 4230.8 | G53: ='Daily PnL Log'!G1284 -> -3114.6 | H53: ='Daily PnL Log'!H1284 -> 0 | I53: ='Daily PnL Log'!I1284 -> 0 | ... N53: ='Daily PnL Log'!N1284 -> 37871.4 | O53: =IF(C53<>"",O52+C53,"") -> 91090.5 | P53: =IF(D53<>"",P52+D53,"") -> 9196.7 | Q53: =IF(E53<>"",Q52+E53,"") -> 0 | R53: =IF(F53<>"",R52+F53,"") -> 12459 | S53: =IF(G53<>"",S52+G53,"") -> -35112.8 | T53: =IF(H53<>"",T52+H53,"") -> 0 | U53: =IF(I53<>"",U52+I53,"") -> 0 | V53: =IF(J53<>"",V52+J53,"") -> 77633.4 | W53: =IF('Daily PnL Log'!W1284<>"",'Daily PnL Log'!W1284,"") -> 518237 | X53: =IF('Daily PnL Log'!X1284<>"",'Daily PnL Log'!X1284,"") -> 0.073077376 | Y53: =IF('Daily PnL Log'!Y1284<>"",'Daily PnL Log'!Y1284,"") | Z53: =IF('Daily PnL Log'!Z1284<>"",'Daily PnL Log'!Z1284,"") | AA53: =IF('Daily PnL Log'!AA1284<>"",'Daily PnL Log'!AA1284,"") | AB53: =IF('Daily PnL Log'!AB1284<>"",'Daily PnL Log'!AB1284,"") | AC53: =IF('Daily PnL Log'!AC1284<>"",'Daily PnL Log'!AC1284,"") -> 94209.84
A54: =TEXT(B54,"mmm") -> Jan | B54: ='Daily PnL Log'!B1285 -> 46030 | C54: ='Daily PnL Log'!C1285 -> -9742.6 | D54: ='Daily PnL Log'!D1285 -> -7136 | E54: ='Daily PnL Log'!E1285 -> 0 | F54: ='Daily PnL Log'!F1285 -> -5227.2 | G54: ='Daily PnL Log'!G1285 -> 8633.6 | H54: ='Daily PnL Log'!H1285 -> 0 | I54: ='Daily PnL Log'!I1285 -> 0 | ... N54: ='Daily PnL Log'!N1285 -> -14427.64 | O54: =IF(C54<>"",O53+C54,"") -> 81347.9 | P54: =IF(D54<>"",P53+D54,"") -> 2060.7 | Q54: =IF(E54<>"",Q53+E54,"") -> 0 | R54: =IF(F54<>"",R53+F54,"") -> 7231.8 | S54: =IF(G54<>"",S53+G54,"") -> -26479.2 | T54: =IF(H54<>"",T53+H54,"") -> 0 | U54: =IF(I54<>"",U53+I54,"") -> 0 | V54: =IF(J54<>"",V53+J54,"") -> 64161.2 | W54: =IF('Daily PnL Log'!W1285<>"",'Daily PnL Log'!W1285,"") -> 589490 | X54: =IF('Daily PnL Log'!X1285<>"",'Daily PnL Log'!X1285,"") -> -0.024474783 | Y54: =IF('Daily PnL Log'!Y1285<>"",'Daily PnL Log'!Y1285,"") | Z54: =IF('Daily PnL Log'!Z1285<>"",'Daily PnL Log'!Z1285,"") | AA54: =IF('Daily PnL Log'!AA1285<>"",'Daily PnL Log'!AA1285,"") | AB54: =IF('Daily PnL Log'!AB1285<>"",'Daily PnL Log'!AB1285,"") | AC54: =IF('Daily PnL Log'!AC1285<>"",'Daily PnL Log'!AC1285,"") -> 108435.65
A55: =TEXT(B55,"mmm") -> Jan | B55: ='Daily PnL Log'!B1286 -> 46031 | C55: ='Daily PnL Log'!C1286 -> 1612.9 | D55: ='Daily PnL Log'!D1286 -> 4726.4 | E55: ='Daily PnL Log'!E1286 -> 0 | F55: ='Daily PnL Log'!F1286 -> -5952.5 | G55: ='Daily PnL Log'!G1286 -> -2494.8 | H55: ='Daily PnL Log'!H1286 -> 0 | I55: ='Daily PnL Log'!I1286 -> 0 | ... N55: ='Daily PnL Log'!N1286 -> -3526.17 | O55: =IF(C55<>"",O54+C55,"") -> 82960.8 | P55: =IF(D55<>"",P54+D55,"") -> 6787.1 | Q55: =IF(E55<>"",Q54+E55,"") -> 0 | R55: =IF(F55<>"",R54+F55,"") -> 1279.3 | S55: =IF(G55<>"",S54+G55,"") -> -28974 | T55: =IF(H55<>"",T54+H55,"") -> 0 | U55: =IF(I55<>"",U54+I55,"") -> 0 | V55: =IF(J55<>"",V54+J55,"") -> 62053.2 | W55: =IF('Daily PnL Log'!W1286<>"",'Daily PnL Log'!W1286,"") -> 562260 | X55: =IF('Daily PnL Log'!X1286<>"",'Daily PnL Log'!X1286,"") -> -0.0062714225 | Y55: =IF('Daily PnL Log'!Y1286<>"",'Daily PnL Log'!Y1286,"") | Z55: =IF('Daily PnL Log'!Z1286<>"",'Daily PnL Log'!Z1286,"") | AA55: =IF('Daily PnL Log'!AA1286<>"",'Daily PnL Log'!AA1286,"") | AB55: =IF('Daily PnL Log'!AB1286<>"",'Daily PnL Log'!AB1286,"") | AC55: =IF('Daily PnL Log'!AC1286<>"",'Daily PnL Log'!AC1286,"") -> 74684.98
A56: =TEXT(B56,"mmm") -> Jan | B56: ='Daily PnL Log'!B1287 -> 46034 | C56: ='Daily PnL Log'!C1287 -> -32546.3 | D56: ='Daily PnL Log'!D1287 -> 4261.2 | E56: ='Daily PnL Log'!E1287 -> 0 | F56: ='Daily PnL Log'!F1287 -> -113515.1 | G56: ='Daily PnL Log'!G1287 -> 14792.5 | H56: ='Daily PnL Log'!H1287 -> 0 | I56: ='Daily PnL Log'!I1287 -> 0 | ... N56: ='Daily PnL Log'!N1287 -> -129507.38 | O56: =IF(C56<>"",O55+C56,"") -> 50414.5 | P56: =IF(D56<>"",P55+D56,"") -> 11048.3 | Q56: =IF(E56<>"",Q55+E56,"") -> 0 | R56: =IF(F56<>"",R55+F56,"") -> -112235.8 | S56: =IF(G56<>"",S55+G56,"") -> -14181.5 | T56: =IF(H56<>"",T55+H56,"") -> 0 | U56: =IF(I56<>"",U55+I56,"") -> 0 | V56: =IF(J56<>"",V55+J56,"") -> -64954.5 | W56: =IF('Daily PnL Log'!W1287<>"",'Daily PnL Log'!W1287,"") -> 485862 | X56: =IF('Daily PnL Log'!X1287<>"",'Daily PnL Log'!X1287,"") -> -0.26655178 | Y56: =IF('Daily PnL Log'!Y1287<>"",'Daily PnL Log'!Y1287,"") -> -329.5 | Z56: =IF('Daily PnL Log'!Z1287<>"",'Daily PnL Log'!Z1287,"") | AA56: =IF('Daily PnL Log'!AA1287<>"",'Daily PnL Log'!AA1287,"") | AB56: =IF('Daily PnL Log'!AB1287<>"",'Daily PnL Log'!AB1287,"") | AC56: =IF('Daily PnL Log'!AC1287<>"",'Daily PnL Log'!AC1287,"") -> -19479.7
A57: =TEXT(B57,"mmm") -> Jan | B57: ='Daily PnL Log'!B1288 -> 46035 | C57: ='Daily PnL Log'!C1288 -> 568.3 | D57: ='Daily PnL Log'!D1288 -> 42148.2 | E57: ='Daily PnL Log'!E1288 -> 0 | F57: ='Daily PnL Log'!F1288 -> 2901.5 | G57: ='Daily PnL Log'!G1288 -> 7433.8 | H57: ='Daily PnL Log'!H1288 -> 0 | I57: ='Daily PnL Log'!I1288 -> 0 | ... N57: ='Daily PnL Log'!N1288 -> 51931.55 | O57: =IF(C57<>"",O56+C57,"") -> 50982.8 | P57: =IF(D57<>"",P56+D57,"") -> 53196.5 | Q57: =IF(E57<>"",Q56+E57,"") -> 0 | R57: =IF(F57<>"",R56+F57,"") -> -109334.3 | S57: =IF(G57<>"",S56+G57,"") -> -6747.7 | T57: =IF(H57<>"",T56+H57,"") -> 0 | U57: =IF(I57<>"",U56+I57,"") -> 0 | V57: =IF(J57<>"",V56+J57,"") -> -11902.7 | W57: =IF('Daily PnL Log'!W1288<>"",'Daily PnL Log'!W1288,"") -> 504410 | X57: =IF('Daily PnL Log'!X1288<>"",'Daily PnL Log'!X1288,"") -> 0.10295504 | Y57: =IF('Daily PnL Log'!Y1288<>"",'Daily PnL Log'!Y1288,"") | Z57: =IF('Daily PnL Log'!Z1288<>"",'Daily PnL Log'!Z1288,"") | AA57: =IF('Daily PnL Log'!AA1288<>"",'Daily PnL Log'!AA1288,"") | AB57: =IF('Daily PnL Log'!AB1288<>"",'Daily PnL Log'!AB1288,"") | AC57: =IF('Daily PnL Log'!AC1288<>"",'Daily PnL Log'!AC1288,"") -> 21252.55
